[2025-03-11T05:11:31.358+0000] {taskinstance.py:1159} INFO - Dependencies all met for dep_context=non-requeueable deps ti=<TaskInstance: ingest_bronze_layer_dag.fetch_purchases manual__2025-03-11T05:07:16+00:00 [queued]>
[2025-03-11T05:11:31.362+0000] {taskinstance.py:1159} INFO - Dependencies all met for dep_context=requeueable deps ti=<TaskInstance: ingest_bronze_layer_dag.fetch_purchases manual__2025-03-11T05:07:16+00:00 [queued]>
[2025-03-11T05:11:31.362+0000] {taskinstance.py:1361} INFO - Starting attempt 3 of 3
[2025-03-11T05:11:31.368+0000] {taskinstance.py:1382} INFO - Executing <Task(_PythonDecoratedOperator): fetch_purchases> on 2025-03-11 05:07:16+00:00
[2025-03-11T05:11:31.370+0000] {standard_task_runner.py:57} INFO - Started process 5949 to run task
[2025-03-11T05:11:31.372+0000] {standard_task_runner.py:84} INFO - Running: ['***', 'tasks', 'run', 'ingest_bronze_layer_dag', 'fetch_purchases', 'manual__2025-03-11T05:07:16+00:00', '--job-id', '42', '--raw', '--subdir', 'DAGS_FOLDER/ingesting_pipeline.py', '--cfg-path', '/tmp/tmpp24vta2r']
[2025-03-11T05:11:31.374+0000] {standard_task_runner.py:85} INFO - Job 42: Subtask fetch_purchases
[2025-03-11T05:11:31.397+0000] {task_command.py:416} INFO - Running <TaskInstance: ingest_bronze_layer_dag.fetch_purchases manual__2025-03-11T05:07:16+00:00 [running]> on host 50aa08a06197
[2025-03-11T05:11:31.604+0000] {taskinstance.py:1662} INFO - Exporting env vars: AIRFLOW_CTX_DAG_OWNER='Andrew Tran' AIRFLOW_CTX_DAG_ID='ingest_bronze_layer_dag' AIRFLOW_CTX_TASK_ID='fetch_purchases' AIRFLOW_CTX_EXECUTION_DATE='2025-03-11T05:07:16+00:00' AIRFLOW_CTX_TRY_NUMBER='3' AIRFLOW_CTX_DAG_RUN_ID='manual__2025-03-11T05:07:16+00:00'
[2025-03-11T05:11:31.609+0000] {base.py:73} INFO - Using connection ID 'postgres_source_db' for task execution.
[2025-03-11T05:11:31.614+0000] {logging_mixin.py:154} INFO - Incremental time: 1900-01-01 00:00:00
[2025-03-11T05:11:31.617+0000] {warnings.py:109} WARNING - /opt/***/dags/ingesting_pipeline.py:58: UserWarning: pandas only supports SQLAlchemy connectable (engine/connection) or database string URI or sqlite3 DBAPI2 connection. Other DBAPI2 objects are not tested. Please consider using SQLAlchemy.
  df = pd.read_sql(query, conn)

[2025-03-11T05:11:31.618+0000] {taskinstance.py:1937} ERROR - Task failed with exception
Traceback (most recent call last):
  File "/home/airflow/.local/lib/python3.10/site-packages/pandas/io/sql.py", line 2262, in execute
    cur.execute(sql, *args)
psycopg2.errors.UndefinedTable: relation "purchases_data" does not exist
LINE 3:         FROM purchases_data
                     ^


The above exception was the direct cause of the following exception:

Traceback (most recent call last):
  File "/home/airflow/.local/lib/python3.10/site-packages/airflow/decorators/base.py", line 221, in execute
    return_value = super().execute(context)
  File "/home/airflow/.local/lib/python3.10/site-packages/airflow/operators/python.py", line 192, in execute
    return_value = self.execute_callable()
  File "/home/airflow/.local/lib/python3.10/site-packages/airflow/operators/python.py", line 209, in execute_callable
    return self.python_callable(*self.op_args, **self.op_kwargs)
  File "/opt/airflow/dags/ingesting_pipeline.py", line 58, in fetch_purchases
    df = pd.read_sql(query, conn)
  File "/home/airflow/.local/lib/python3.10/site-packages/pandas/io/sql.py", line 654, in read_sql
    return pandas_sql.read_query(
  File "/home/airflow/.local/lib/python3.10/site-packages/pandas/io/sql.py", line 2326, in read_query
    cursor = self.execute(sql, params)
  File "/home/airflow/.local/lib/python3.10/site-packages/pandas/io/sql.py", line 2274, in execute
    raise ex from exc
pandas.errors.DatabaseError: Execution failed on sql '
        SELECT *, NOW() as extracted_at
        FROM purchases_data
        WHERE updated_at > '1900-01-01 00:00:00'
        ': relation "purchases_data" does not exist
LINE 3:         FROM purchases_data
                     ^

[2025-03-11T05:11:31.622+0000] {taskinstance.py:1400} INFO - Marking task as FAILED. dag_id=ingest_bronze_layer_dag, task_id=fetch_purchases, execution_date=20250311T050716, start_date=20250311T051131, end_date=20250311T051131
[2025-03-11T05:11:31.629+0000] {standard_task_runner.py:104} ERROR - Failed to execute job 42 for task fetch_purchases (Execution failed on sql '
        SELECT *, NOW() as extracted_at
        FROM purchases_data
        WHERE updated_at > '1900-01-01 00:00:00'
        ': relation "purchases_data" does not exist
LINE 3:         FROM purchases_data
                     ^
; 5949)
[2025-03-11T05:11:31.645+0000] {local_task_job_runner.py:228} INFO - Task exited with return code 1
[2025-03-11T05:11:31.652+0000] {taskinstance.py:2778} INFO - 0 downstream tasks scheduled from follow-on schedule check
