[2025-03-11T14:31:43.853+0000] {taskinstance.py:1159} INFO - Dependencies all met for dep_context=non-requeueable deps ti=<TaskInstance: ingest_bronze_layer_dag.prepare_dag_execution manual__2025-03-11T14:31:38+00:00 [queued]>
[2025-03-11T14:31:43.866+0000] {taskinstance.py:1159} INFO - Dependencies all met for dep_context=requeueable deps ti=<TaskInstance: ingest_bronze_layer_dag.prepare_dag_execution manual__2025-03-11T14:31:38+00:00 [queued]>
[2025-03-11T14:31:43.866+0000] {taskinstance.py:1361} INFO - Starting attempt 1 of 1
[2025-03-11T14:31:43.881+0000] {taskinstance.py:1382} INFO - Executing <Task(PythonOperator): prepare_dag_execution> on 2025-03-11 14:31:38+00:00
[2025-03-11T14:31:43.896+0000] {standard_task_runner.py:57} INFO - Started process 16346 to run task
[2025-03-11T14:31:43.901+0000] {standard_task_runner.py:84} INFO - Running: ['***', 'tasks', 'run', 'ingest_bronze_layer_dag', 'prepare_dag_execution', 'manual__2025-03-11T14:31:38+00:00', '--job-id', '420', '--raw', '--subdir', 'DAGS_FOLDER/ingesting_pipeline.py', '--cfg-path', '/tmp/tmpgwsgo7uy']
[2025-03-11T14:31:43.904+0000] {standard_task_runner.py:85} INFO - Job 420: Subtask prepare_dag_execution
[2025-03-11T14:31:43.959+0000] {task_command.py:416} INFO - Running <TaskInstance: ingest_bronze_layer_dag.prepare_dag_execution manual__2025-03-11T14:31:38+00:00 [running]> on host 41ccd9d1769c
[2025-03-11T14:31:44.195+0000] {taskinstance.py:1662} INFO - Exporting env vars: AIRFLOW_CTX_DAG_OWNER='Andrew Tran' AIRFLOW_CTX_DAG_ID='ingest_bronze_layer_dag' AIRFLOW_CTX_TASK_ID='prepare_dag_execution' AIRFLOW_CTX_EXECUTION_DATE='2025-03-11T14:31:38+00:00' AIRFLOW_CTX_TRY_NUMBER='1' AIRFLOW_CTX_DAG_RUN_ID='manual__2025-03-11T14:31:38+00:00'
[2025-03-11T14:31:44.210+0000] {base.py:73} INFO - Using connection ID 'postgres_source_db' for task execution.
[2025-03-11T14:31:44.216+0000] {warnings.py:109} WARNING - /opt/***/dags/ingesting_pipeline.py:136: UserWarning: pandas only supports SQLAlchemy connectable (engine/connection) or database string URI or sqlite3 DBAPI2 connection. Other DBAPI2 objects are not tested. Please consider using SQLAlchemy.
  df = pd.read_sql(query, conn)

[2025-03-11T14:31:44.217+0000] {taskinstance.py:1937} ERROR - Task failed with exception
Traceback (most recent call last):
  File "/home/airflow/.local/lib/python3.10/site-packages/pandas/io/sql.py", line 2262, in execute
    cur.execute(sql, *args)
psycopg2.errors.UndefinedTable: relation "bronze_layer.bronze_purchases" does not exist
LINE 1: SELECT MAX(updated_at) FROM bronze_layer.bronze_purchases
                                    ^


The above exception was the direct cause of the following exception:

Traceback (most recent call last):
  File "/home/airflow/.local/lib/python3.10/site-packages/airflow/operators/python.py", line 192, in execute
    return_value = self.execute_callable()
  File "/home/airflow/.local/lib/python3.10/site-packages/airflow/operators/python.py", line 209, in execute_callable
    return self.python_callable(*self.op_args, **self.op_kwargs)
  File "/opt/airflow/dags/ingesting_pipeline.py", line 245, in prepare_dag_execution
    incremental_time = get_latest_updated_at_from_table(pg_source_hook, table_name=DB_CONFIG["bronze"]["tables"]["purchases"], schema_name=DB_CONFIG["bronze"]["schema"])
  File "/opt/airflow/dags/ingesting_pipeline.py", line 146, in get_latest_updated_at_from_table
    df = extract_data_from_source(source_hook, query)
  File "/opt/airflow/dags/ingesting_pipeline.py", line 136, in extract_data_from_source
    df = pd.read_sql(query, conn)
  File "/home/airflow/.local/lib/python3.10/site-packages/pandas/io/sql.py", line 654, in read_sql
    return pandas_sql.read_query(
  File "/home/airflow/.local/lib/python3.10/site-packages/pandas/io/sql.py", line 2326, in read_query
    cursor = self.execute(sql, params)
  File "/home/airflow/.local/lib/python3.10/site-packages/pandas/io/sql.py", line 2274, in execute
    raise ex from exc
pandas.errors.DatabaseError: Execution failed on sql 'SELECT MAX(updated_at) FROM bronze_layer.bronze_purchases': relation "bronze_layer.bronze_purchases" does not exist
LINE 1: SELECT MAX(updated_at) FROM bronze_layer.bronze_purchases
                                    ^

[2025-03-11T14:31:44.224+0000] {taskinstance.py:1400} INFO - Marking task as FAILED. dag_id=ingest_bronze_layer_dag, task_id=prepare_dag_execution, execution_date=20250311T143138, start_date=20250311T143143, end_date=20250311T143144
[2025-03-11T14:31:44.232+0000] {standard_task_runner.py:104} ERROR - Failed to execute job 420 for task prepare_dag_execution (Execution failed on sql 'SELECT MAX(updated_at) FROM bronze_layer.bronze_purchases': relation "bronze_layer.bronze_purchases" does not exist
LINE 1: SELECT MAX(updated_at) FROM bronze_layer.bronze_purchases
                                    ^
; 16346)
[2025-03-11T14:31:44.249+0000] {local_task_job_runner.py:228} INFO - Task exited with return code 1
[2025-03-11T14:31:44.396+0000] {taskinstance.py:2778} INFO - 0 downstream tasks scheduled from follow-on schedule check
